Workbook

Sheet 0_README
A1: DAY 22 — MONETIZATION MODEL
A2: AI Pricing · GTM · Evidence — AI-IN-ACTION Track 1
A4: QUY ƯỚC MÀU — CHỈ ĐIỀN VÀO Ô MÀU VÀNG
A5: Ô VÀNG, chữ xanh dương | B5: Ô bạn phải điền
A6: Ô XÁM, chữ đen | B6: Công thức tự tính — KHÔNG SỬA
A7: Chữ xanh lá | B7: Link sang tab khác
A8: Ô XÁM đậm nhạt | B8: Bảng tham chiếu, chỉ đọc
A10: THỨ TỰ LÀM — 6 TRẠM, 120 PHÚT
A11: Trạm 1 · 15' | B11: Ngân sách khách & định nghĩa Job → điền S1–S2 của tab 1_Cost_Job
A12: Trạm 2 · 20' | B12: Value Metric → tab 3_Value_Metric
A13: Trạm 3 · 30' | B13: Cost/Job, giá sàn & giá trần → tab 1_Cost_Job (S3–S8) rồi 2_Pricing
A14: Trạm 4 · 20' | B14: Kênh phân phối & Affordability Test → tab 4_Channel_Fit
A15: Trạm 5 · 15' | B15: Pain Moment & 90-Day Plan → tab 5_90Day_Plan
A16: Trạm 6 · 20' | B16: Evidence Pack & ráp One-Pager → tab 5_90Day_Plan + file .docx
A18: 3 QUY TẮC KHÔNG ĐƯỢC PHÁ
A19: 1. Chia cho số job HOÀN THÀNH, không phải số job đã thử.
A20: 2. HITL và Retry không được để 0 nếu không có lý do viết ra được.
A21: 3. Mọi con số giá API phải có NGÀY kiểm tra (xem tab 6_Benchmarks).
A23: Giá tham chiếu trong workbook này được chốt ngày 26/08/2026. Nhiều mức giá là KHUYẾN MẠI CÓ HẠN.
A24: Bạn PHẢI tự mở lại trang giá của nhà cung cấp và cập nhật — đây là một phần của bài tập.

Sheet 1_Cost_Job
A1: TAB 1 — COST/JOB CALCULATOR
A2: Trạm 1 (S1–S2) và Trạm 3 (S3–S8). Chỉ điền ô vàng.
E3: LÝ DO / NGUỒN CHO TỪNG Ô VÀNG (CaTối — AI trực inbox Facebook cho shop thời trang trên Haravan)
A4: S1. ĐỊNH NGHĨA JOB
A5: 1 job của bạn là gì? | B5: 1 hội thoại hỏi mua trên Fanpage được AI xử lý xong: khách nhận đủ thông tin (giá/size/còn hàng/phí ship) hoặc AI lên đơn nháp vào Haravan, KHÔNG có tin nhắn nào do người của shop gõ, và khách không nhắn lại trong 24h. Không tính: hội thoại chuyển chủ shop, khách bỏ ngang trước khi AI trả lời đủ, lỗi kỹ thuật, spam. | D5: Phải là thứ KHÁCH coi là giá trị — không phải '1 request' | E5: Đếm tự động từ log Messenger webhook (sender = page bot vs. người). Mốc 24h trùng cửa sổ nhắn tin chuẩn của Messenger Platform.
A6: Biến thể HITL: A hay B? | B6: A | D6: A = khách tự xử lý ca escalate · B = BẠN chịu (outcome/managed) | E6: Biến thể A: CaTối bán phần mềm; 30% ca AI chuyển lại do CHỦ SHOP tự trả lời (như họ đang làm hôm nay) và KHÔNG bị tính tiền. QA nội bộ của CaTối vẫn vào COGS (S7).
A8: S2. KHỐI LƯỢNG
A9: Số job THỬ / tháng | B9: 1500 | C9: job | E9: Ước tính 1 shop mục tiêu ≈ 50 hội thoại/ngày × 30. Phân khúc chọn: shop 30–100 hội thoại/ngày. Kiểm chứng bằng log 5 shop pilot (tháng 1).
A10: Containment rate (AI tự làm xong) | B10: 0.7 | D10: Chưa đo → ước tính và ghi rõ | E10: ƯỚC TÍNH — chưa có eval. Giả thuyết: phần lớn inbox là câu hỏi giá/size/còn hàng/ship trả lời được từ dữ liệu Haravan. Đo thật trên 300 hội thoại pilot trước 13/11/2026.
A11: → Số job HOÀN THÀNH / tháng | B11: =B9*B10 -> 1050 | C11: job | D11: MẪU SỐ của Cost/Job
A12: → Số job KHÔNG xong / tháng | B12: =B9-B11 -> 450 | C12: job | D12: Số ca phải escalate
A14: S3. API — LLM
A15: Giá input ($ / 1M token) | B15: 1 | D15: Claude Haiku 4.5 — xem tab 6_Benchmarks | E15: Claude Haiku 4.5 — giá LIST (không phải KM), kiểm tra 08/10/2026 tại platform.claude.com/docs/en/about-claude/pricing
A16: Giá output ($ / 1M token) | B16: 5 | E16: Haiku 4.5 output $5/1M — kiểm tra 08/10/2026
A17: Giá cache WRITE ($ / 1M token) | B17: 2 | D17: Anthropic 5-phút = 1,25× input | E17: Dùng giá cache write 1 GIỜ ($2 = 2× input), không dùng 5 phút: khách inbox trả lời cách nhau vài phút → cache 5' sẽ hết hạn giữa các lượt. Bảo thủ.
A18: Giá cache READ ($ / 1M token) | B18: 0.1 | D18: ≈ 0,1× input (giảm 90%) | E18: Cache read 0,1× input = $0,10/1M (Haiku 4.5) — kiểm tra 08/10/2026
A19: Số lượt (turns) / job | B19: 6 | C19: lượt | E19: Hỏi giá → size → còn màu? → phí ship → địa chỉ/SĐT → xác nhận đơn. Ước tính, đo lại từ log pilot.
A20: Token input CACHE ĐƯỢC / lượt | B20: 3500 | C20: token | D20: System prompt + KB + few-shot | E20: System prompt + chính sách shop (đổi trả, ship) + bảng size + danh mục ~50 SP bán chạy + tool schema (Haiku 4.5: 496 token tool-use). Tiếng Việt tốn token hơn tiếng Anh.
A21: Token input FRESH / lượt | B21: 1400 | C21: token | D21: Câu hỏi khách + dữ liệu động | E21: Tin khách + lịch sử hội thoại + kết quả tool (tồn kho/giá từ Haravan API) + ẢNH khách gửi (~30% hội thoại có ảnh chụp mẫu, giữ trong lịch sử).
A22: Token output / lượt | B22: 200 | C22: token | E22: Câu trả lời chat ngắn (~120 token) + JSON gọi tool (~80 token).
A23: → Cache write / job | B23: =B20*B17/1000000 -> 0.007
A24: → Cache read / job | B24: =(B19-1)*B20*B18/1000000 -> 0.00175
A25: → Input fresh / job | B25: =B19*B21*B15/1000000 -> 0.0084
A26: → Output / job | B26: =B19*B22*B16/1000000 -> 0.006
A27: → LLM / job — CÓ prompt caching | B27: =SUM(B23:B26) -> 0.02315
A28: → LLM / job — KHÔNG cache | B28: =B19*(B20+B21)*B15/1000000+B26 -> 0.0354
A29: → % tiết kiệm nhờ caching | B29: =IF(B28=0,0,1-B27/B28) -> 0.3460452 | D29: Đòn bẩy rẻ nhất bạn có
A30: Dùng Batch API? (1 = có, 0 = không) | B30: 0 | D30: Batch giảm 50% — chỉ khi job KHÔNG cần realtime | E30: KHÔNG dùng Batch: khách đang chờ trả lời realtime trên Messenger. Batch chỉ dùng cho chạy eval offline.
A31: → LLM / job sau Batch | B31: =B27*(1-B30*0.5) -> 0.02315
A33: S4. API — SPEECH (để 0 nếu sản phẩm không có thoại)
A34: Giá STT ($ / phút) | B34: 0 | D34: Deepgram streaming list $0,0077/phút | E34: Không có thoại — sản phẩm chỉ chạy text trên Messenger.
A35: Số phút audio / job | B35: 0 | C35: phút | E35: Không có thoại.
A36: Giá TTS ($ / 1M ký tự) | B36: 0 | D36: ElevenLabs Flash $50 · Google Standard $4 | E36: Không có thoại.
A37: Số ký tự TTS / job | B37: 0 | C37: ký tự | D37: ≈ 900 ký tự cho mỗi phút bot nói | E37: Không có thoại.
A38: → Speech / job | B38: =B34*B35+B36*B37/1000000 -> 0
A40: S5. INFRA
A41: Infra / job ($) | B41: 0.005 | D41: Vector DB, embedding, storage, logging | E41: ≈ $190/tháng ở quy mô 30 shop (45.000 hội thoại): hosting webhook+DB $90 · eval hồi quy hằng tuần $30 · logging/observability $50 · embedding+vector search catalog $20 → $0,0042, làm tròn lên $0,005 cho lưu ảnh/egress. Ở quy mô pilot 5 shop, con số này ≈ $0,02 (xem tab 7).
A42: Telephony ($ / phút) | B42: 0 | E42: Không có telephony. Messenger Platform không thu phí tin nhắn trả lời trong cửa sổ 24h.
A43: → Infra / job | B43: =B41+B42*B35 -> 0.005
A45: S6. RETRY
...

Sheet 2_Pricing
A1: TAB 2 — PRICING SANITY CHECK
A2: Trạm 3. Cost/Job tự lấy từ tab 1. Bạn điền giá bán và các con số neo giá.
E3: LÝ DO / NGUỒN
A4: GIÁ SÀN
A5: Cost/Job (từ tab 1_Cost_Job) | B5: ='1_Cost_Job'!B66 -> 0.047041118 | C5: $/job
A6: Hệ số an toàn tối thiểu | B6: 3 | C6: × | D6: Giá bán ≥ 3 × Cost/Job | E6: Giữ đúng ngưỡng 3× của lab.
A7: → GIÁ SÀN | B7: =B5*B6 -> 0.14112335 | C7: $/job
A9: GIÁ TRẦN — NEO THEO THỨ KHÁCH ĐANG CHI
A10: Giá trị khách tiết kiệm được / tháng ($) | B10: =(7000000+40*60000)/'1_Cost_Job'!$B$68 -> 358.91562 | D10: Neo theo giá trị | E10: Giá trị khách nhận/tháng = lương nhân viên trực page 7tr₫ + lãi gộp của đơn đêm không bị mất (giả định 40 đơn × 60.000₫) = 9,4tr₫. GIẢ ĐỊNH — phỏng vấn 5 shop pilot.
A11: Số job / tháng của 1 khách | B11: ='1_Cost_Job'!B11 -> 1050 | C11: job | E11: Số job HOÀN THÀNH/tháng của 1 shop (1.500 × 70%) — vì chỉ hội thoại xử lý xong mới bị tính tiền.
A12: → Trần theo giá trị — mức 10% | B12: =IF(B11=0,0,B10*0.1/B11) -> 0.03418244 | C12: $/job
A13: → Trần theo giá trị — mức 25% | B13: =IF(B11=0,0,B10*0.25/B11) -> 0.085456099 | C13: $/job
A14: Lương / tháng của vị trí bị thay ($) | B14: =7000000/'1_Cost_Job'!$B$68 -> 267.27759 | D14: Neo theo nhân công | E14: Lương 1 nhân viên trực page/CSKH online full-time ≈ 7tr₫/tháng (giả định, kiểm chứng khi phỏng vấn shop). Chọn neo này vì chủ shop TỰ KIỂM CHỨNG được (họ đang trả lương).
A15: → Trần theo nhân công — mức 50% | B15: =IF(B11=0,0,B14*0.5/B11) -> 0.12727504 | C15: $/job
A16: → Trần theo nhân công — mức 70% | B16: =IF(B11=0,0,B14*0.7/B11) -> 0.17818506 | C16: $/job
A18: GIÁ BÁN CỦA BẠN
A19: ★ Giá bán đề xuất ($ / job) | B19: =3900/'1_Cost_Job'!$B$68 -> 0.1489118 | C19: $/job | D19: Tham chiếu: Intercom Fin $0,99 · Zendesk $1,50 | E19: 3.900₫ / hội thoại xử lý xong (≈$0,149). Nằm giữa 50–70% lương (3.333–4.667₫/job). Rẻ hơn Intercom Fin $0,99 ~6,6× vì neo theo lương VN, không theo lương Mỹ.
A20: → Bội số so với Cost/Job | B20: =IF(B5=0,0,B19/B5) -> 3.1655667
A21: → GROSS MARGIN | B21: =IF(B19=0,0,(B19-B5)/B19) -> 0.6841008
A22: → Đèn: bội số ≥ 3? | B22: =IF(B20>=B6,"OK — ĐẠT","KHÔNG ĐẠT — quay lại tab 1") -> OK — ĐẠT
A23: → Đèn: Gross Margin | B23: =IF(B21>=0.6,"OK — AN TOÀN (≥60%)",IF(B21>=0.5,"CẢNH BÁO (50–60%)","NGUY HIỂM (<50%)")) -> OK — AN TOÀN (≥60%)
A24: → Đèn: GM có cao bất thường? | B24: =IF(B21>0.85,"NGHI NGỜ — nhiều khả năng bạn quên một khoản chi phí","OK") -> OK
A25: → Giá bán nằm trong vùng neo? | B25: =IF(AND(B19>=B7,B19<=MAX(B13,B16)),"OK — trong vùng giá bán","XEM LẠI — ngoài vùng giá sàn/trần") -> OK — trong vùng giá bán
A27: BREAKEVEN CONTAINMENT — ngưỡng sống còn
A28: Ký hiệu: v = chi phí biến đổi / job thử · q = QA / job thử · e = chi phí 1 ca escalate
A29: v — chi phí biến đổi / job thử | B29: ='1_Cost_Job'!B31+'1_Cost_Job'!B38+'1_Cost_Job'!B43+'1_Cost_Job'!B47 -> 0.029539
A30: q — QA nội bộ / job thử | B30: ='1_Cost_Job'!B51*('1_Cost_Job'!B52/60)*'1_Cost_Job'!B50 -> 0.0033897827
A31: e — chi phí 1 ca escalate | B31: =IF('1_Cost_Job'!B6="B",('1_Cost_Job'!B53/60)*'1_Cost_Job'!B50,0) -> 0
A32: Gross Margin mục tiêu | B32: 0.6 | E32: GM mục tiêu theo lab.
A33: ★ Containment tối thiểu cần đạt | B33: =IF((B19*(1-B32)+B31)=0,0,(B29+B30+B31)/(B19*(1-B32)+B31)) -> 0.5528236 | D33: Công thức: R ≥ (v+q+e) / (P×(1−GM)+e)
A34: Containment hiện tại (từ tab 1) | B34: ='1_Cost_Job'!B10 -> 0.7
A35: → Kết luận | B35: =IF(B34>=B33,"ĐẠT — mô hình có lãi lành mạnh","CHƯA ĐẠT — phải tăng containment, tăng giá, hoặc đổi biến thể HITL") -> ĐẠT — mô hình có lãi lành mạnh
A37: SENSITIVITY — mô hình gãy ở đâu?
A38: Containment | B38: Cost/Job | C38: Gross Margin | D38: Đánh giá
A39: 0.5 | B39: =($B$29+$B$30+$B$31*(1-A39))/A39 -> 0.065857565 | C39: =IF($B$19=0,0,1-B39/$B$19) -> 0.55774112 | D39: =IF(C39>=0.6,"An toàn",IF(C39>=0.5,"Cảnh báo","Nguy hiểm")) -> Cảnh báo
A40: 0.6 | B40: =($B$29+$B$30+$B$31*(1-A40))/A40 -> 0.054881305 | C40: =IF($B$19=0,0,1-B40/$B$19) -> 0.63145093 | D40: =IF(C40>=0.6,"An toàn",IF(C40>=0.5,"Cảnh báo","Nguy hiểm")) -> An toàn
A41: 0.7 | B41: =($B$29+$B$30+$B$31*(1-A41))/A41 -> 0.047041118 | C41: =IF($B$19=0,0,1-B41/$B$19) -> 0.6841008 | D41: =IF(C41>=0.6,"An toàn",IF(C41>=0.5,"Cảnh báo","Nguy hiểm")) -> An toàn
A42: 0.8 | B42: =($B$29+$B$30+$B$31*(1-A42))/A42 -> 0.041160978 | C42: =IF($B$19=0,0,1-B42/$B$19) -> 0.7235882 | D42: =IF(C42>=0.6,"An toàn",IF(C42>=0.5,"Cảnh báo","Nguy hiểm")) -> An toàn
A43: 0.9 | B43: =($B$29+$B$30+$B$31*(1-A43))/A43 -> 0.036587536 | C43: =IF($B$19=0,0,1-B43/$B$19) -> 0.75430062 | D43: =IF(C43>=0.6,"An toàn",IF(C43>=0.5,"Cảnh báo","Nguy hiểm")) -> An toàn
A44: 0.95 | B44: =($B$29+$B$30+$B$31*(1-A44))/A44 -> 0.034661877 | C44: =IF($B$19=0,0,1-B44/$B$19) -> 0.76723217 | D44: =IF(C44>=0.6,"An toàn",IF(C44>=0.5,"Cảnh báo","Nguy hiểm")) -> An toàn
...

Sheet 3_Value_Metric
A1: TAB 3 — VALUE METRIC SCORECARD
A2: Trạm 2. Chấm 0 / 1 / 2 điểm cho mỗi câu, theo THỰC TẾ HÔM NAY.
E3: BẰNG CHỨNG CHO ĐIỂM (thực tế HÔM NAY 08/10/2026 — sản phẩm đang ở giai đoạn thiết kế/MVP)
A4: A. ATTRIBUTION — bạn đo được kết quả là do AI tạo ra không?
A5: 1. Tôi có log đầy đủ mỗi job AI xử lý, gắn được với kết quả cuối cùng | B5: 1 | E5: Đã thiết kế log theo hội thoại (sender, tool call, kết quả) nhưng chưa chạy với shop thật.
A6: 2. Tôi có bộ eval đo được tỷ lệ AI làm đúng, có số liệu | B6: 0 | E6: CHƯA có eval. Deadline bộ eval 300 hội thoại: 13/11/2026.
A7: 3. Khách hàng đồng ý với cách tôi định nghĩa 'thành công' của một job | B7: 1 | E7: Định nghĩa bám theo cách chủ shop tự hiểu 'khách hỏi xong' + mốc 24h Messenger, nhưng chưa được shop nào xác nhận.
A8: 4. Tôi phân biệt được kết quả do AI tạo ra với kết quả do yếu tố khác | B8: 2 | E8: Có: log Messenger cho biết hội thoại có tin nhắn do người gõ hay không → phân định AI vs. người gần như tuyệt đối (khác với 'doanh số tăng' là thứ KHÔNG attribution được).
A9: 5. Tôi viết được định nghĩa chặt như Intercom: cái gì tính tiền, cái gì không | B9: 2 | E9: Đã viết định nghĩa tính/không tính tiền ở tab 1 ô B5 (kiểu Intercom).
A10: → ĐIỂM ATTRIBUTION (tối đa 10) | B10: =SUM(B5:B9) -> 6
A12: B. AUTONOMY — AI tự chạy hay cần người?
A13: 1. AI hoàn thành job từ đầu đến cuối, không cần người bấm nút giữa chừng | B13: 1 | E13: Tư vấn + báo giá chạy end-to-end; đơn nháp vẫn cần shop bấm xác nhận giao.
A14: 2. Job chạy được ngoài giờ hành chính mà không ai trực | B14: 2 | E14: Chạy 24/7 trên webhook, đây chính là giá trị cốt lõi (ca tối).
A15: 3. Khi AI không chắc, nó tự chuyển tiếp đúng chỗ — không cần người phân loại | B15: 1 | E15: Có rule chuyển người (khiếu nại, đổi trả, giá sỉ, độ tin cậy thấp) nhưng chưa test.
A16: 4. Tỷ lệ ca phải có người can thiệp dưới 20% | B16: 0 | E16: Ước tính 30% chuyển người > ngưỡng 20%.
A17: 5. Người vận hành chỉ kiểm tra mẫu (QA), không xử lý từng ca | B17: 2 | E17: Chủ shop chỉ xử lý ca được chuyển; CaTối QA mẫu 5%.
A18: → ĐIỂM AUTONOMY (tối đa 10) | B18: =SUM(B13:B17) -> 6
A20: GỢI Ý CỦA MODEL
A21: → Value Metric gợi ý | B21: =IF(AND(B10>=7,B18>=7),"OUTCOME",IF(AND(B10>=7,B18<7),"USAGE",IF(AND(B10<7,B18>=7),"USAGE (an toàn)","SEAT hoặc HYBRID"))) -> SEAT hoặc HYBRID
A22: Ngưỡng 7/10 là quy ước của bài tập, không phải chuẩn ngành — dùng để buộc bạn ra quyết định, không phải để thay bạn quyết định.
A24: BENCHMARK NGƯỢC — 2 sản phẩm thật cùng loại job
A25: Tên sản phẩm | B25: Value Metric | C25: Giá công bố | D25: Link nguồn
A26: Intercom Fin (AI agent CSKH) | B26: Outcome — $/resolution | C26: $0,99/outcome · tối thiểu 50 outcome/tháng trên helpdesk bên thứ ba (kiểm tra 08/10/2026) | D26: https://fin.ai/pricing/
A27: Salesforce Agentforce | B27: Usage — $/conversation (hoặc Flex Credits $0,10/action) | C27: $2/conversation · $500/100k Flex Credits · $5/user/tháng (kiểm tra 08/10/2026) | D27: https://www.salesforce.com/agentforce/pricing/
A28: Tham khảo nội địa: Sapo — Chat hợp kênh AI | B28: Không công bố giá AI riêng | C28: Không tìm thấy giá công khai (08/10/2026) — đối thủ trực tiếp ở VN, là lý do Haravan cần partner | D28: https://www.sapo.vn/phan-mem-chat-bot.html
A29: QUYẾT ĐỊNH CUỐI
A30: Value Metric tôi chọn | B30: Hybrid
A31: Nếu KHÁC gợi ý — lý do thị trường là gì? | B31: Không lệch gợi ý (model: SEAT hoặc HYBRID; Attribution 6/10, Autonomy 6/10). Không chọn Outcome thuần vì chưa có eval. Không chọn Seat vì 1 shop chỉ 1–2 người dùng nhưng số hội thoại chênh 10× giữa shop nhỏ và lớn → Seat lỗ ở shop lớn. Lý do thị trường: SME VN quen trả gói cố định → cần phần tối thiểu dễ dự đoán.
A32: Decision Note — câu 1: tôi chọn đơn vị nào? | B32: Hybrid: phí TỐI THIỂU 1.560.000₫/tháng (đã gồm 400 hội thoại xử lý xong đầu tiên) + 3.900₫ cho mỗi hội thoại xử lý xong từ thứ 401. Shop tự đặt trần chi tiêu/tháng; chạm trần thì hội thoại mới trả về inbox cho người. Không tính tiền ca chuyển người, khách bỏ ngang, lỗi kỹ thuật.
A33: Decision Note — câu 2: bằng chứng Attribution / Autonomy? | B33: Attribution 6/10: 'xử lý xong' đo thẳng từ log Messenger (có/không có tin do người gõ + không nhắn lại 24h) nên phân định AI vs người gần tuyệt đối — nhưng CHƯA có eval độ đúng. Autonomy 6/10: chạy 24/7 không người trực, nhưng containment mới ước tính 70% (30% chuyển chủ shop > ngưỡng 20%).
A34: Decision Note — câu 3: mô hình này lỗ trong tình huống nào? | B34: Lỗ/mỏng khi: (1) phải nâng lên Sonnet 5.5 vì Haiku hiểu sai teencode → GM ~47% (tab 7); (2) Haravan lấy ≥30% doanh thu → GM ~55%; (3) ở quy mô pilot 5 shop, infra cố định chia ít hội thoại → GM ~54%. Containment thấp KHÔNG đốt COGS (Biến thể A) mà đốt doanh thu & lòng tin của shop.

Sheet 4_Channel_Fit
A1: TAB 4 — CHANNEL FIT & AFFORDABILITY TEST
A2: Trạm 4. Chọn ĐÚNG 1 kênh cho 90 ngày đầu — và chứng minh bằng số.
E3: LÝ DO / NGUỒN
A4: A. NGÂN SÁCH CAC — bạn nuôi nổi kênh nào?
A5: ARPU / tháng ($) | B5: ='1_Cost_Job'!B11*'2_Pricing'!B19 -> 156.35739 | E5: ARPU = 1.050 hội thoại xử lý xong × 3.900₫ ≈ 4,1tr₫ ≈ $156/tháng (shop điển hình). Lấy thẳng từ tab 1 & 2.
A6: Gross Margin (từ tab 2_Pricing) | B6: ='2_Pricing'!B21 -> 0.6841008
A7: Phân khúc (SMB / Mid / Enterprise) | B7: SMB | E7: Shop online thời trang 30–100 hội thoại/ngày.
A8: → CAC payback cho phép (tháng) | B8: =IF(B7="SMB",12,IF(B7="Mid",18,24)) -> 12 | C8: tháng | D8: Bessemer, Scaling to $100M (2024)
A9: ★ NGÂN SÁCH CAC / khách | B9: =B5*B6*B8 -> 1283.5706 | D9: ARPU × GM × số tháng payback
A10: → ACV (giá trị hợp đồng / năm) | B10: =B5*12 -> 1876.2887
A12: B. SALES VIABILITY — một AE phải chốt bao nhiêu deal?
A13: Quota / AE / năm ($) | B13: 120000 | D13: Giả định gốc của Tunguz (2016) — thay bằng số thị trường bạn | E13: Quota VN (thay giả định Mỹ $500k của Tunguz): 1 telesales SMB SaaS VN chốt ~5 deal/tháng ở ACV ~$1.900 ≈ $114k → làm tròn $120k. GIẢ ĐỊNH.
A14: Số ngày làm việc / năm | B14: 250 | C14: ngày | E14: Ngày làm việc/năm.
A15: → Số deal / AE / năm | B15: =IF(B10=0,0,B13/B10) -> 63.956044
A16: ★ Số deal / AE / NGÀY | B16: =IF(B14=0,0,B15/B14) -> 0.25582418 | C16: deal/ngày
A17: → Kết luận Sales-Led | B17: =IF(B16<=1,"KHẢ THI về mặt số học","BẤT KHẢ THI — ACV quá thấp để nuôi sales rep") -> KHẢ THI về mặt số học
A19: C. ĐỐI CHIẾU CAC THỰC TẾ CỦA MOTION CÓ SALES
A20: Cost per opportunity ($) | B20: 6300 | D20: ICONIQ 2026 theo phân khúc: $6.300 · $8.000 · $11.200 | E20: ICONIQ State of GTM 2026, tr.22 — mức THẤP NHẤT trong 3 phân khúc (benchmark Mỹ). Bản nội địa hoá telesales VN ở tab 7.
A21: Win rate | B21: 0.25 | E21: Win rate 25% theo ví dụ của lab.
A22: → CAC thực tế ước tính / khách | B22: =IF(B21=0,0,B20/B21) -> 25200
A23: ★ Lệch bao nhiêu lần so với ngân sách CAC? | B23: =IF(B9=0,0,B22/B9) -> 19.632734 | D23: Đây là bằng chứng chọn kênh của bạn
A24: → Kết luận | B24: =IF(B23<=1,"Motion có sales KHẢ THI",IF(B23<=3,"Căng — cần tăng giá hoặc giảm chi phí bán hàng","KHÔNG KHẢ THI — đi PLG hoặc Partner-Led")) -> KHÔNG KHẢ THI — đi PLG hoặc Partner-Led
A26: D. CHẤM ĐIỂM 3 KÊNH (1 = rất kém, 5 = rất tốt)
A27: Tiêu chí | B27: PLG | C27: Sales-Led | D27: Partner-Led
A28: 1. Ngân sách CAC của tôi nuôi nổi kênh này | B28: 4 | C28: 2 | D28: 4 | E28: PLG/Partner rẻ; Sales-Led lệch 19× theo ICONIQ (khả thi chỉ khi nội địa hoá, tab 7).
A29: 2. Khách hàng mục tiêu thực sự mua theo cách này | B29: 2 | C29: 4 | D29: 4 | E29: Chủ shop VN ít tự bỏ 4tr₫/tháng cho tool lạ; họ mua qua telesales hoặc qua kho app của phần mềm bán hàng đang dùng.
A30: 3. Đội hiện tại có năng lực chạy kênh này ngay | B30: 3 | C30: 2 | D30: 3 | E30: Đội = 1 founder kỹ thuật: build app tích hợp được, chưa có sales.
A31: 4. Tôi tiếp cận được điểm nhúng / partner trong 30 ngày | B31: 4 | C31: 3 | D31: 3 | E31: PLG: Messenger app tự kết nối ngay. Partner: Haravan có docs developer công khai, nhưng duyệt listing chưa rõ thời gian.
A32: 5. Kênh này đưa tôi đến ĐÚNG Pain Moment | B32: 3 | C32: 2 | D32: 5 | E32: Haravan giữ catalog + tồn kho + đơn hàng, và HaraSocial là nơi chủ shop đọc inbox → đúng Pain Moment.
A33: 6. Tôi đo được hiệu quả trong vòng 90 ngày | B33: 4 | C33: 4 | D33: 3 | E33: Partner-Led phụ thuộc tiến độ phía Haravan → đo trong 90 ngày khó hơn.
A34: → TỔNG ĐIỂM | B34: =SUM(B28:B33) -> 20 | C34: =SUM(C28:C33) -> 17 | D34: =SUM(D28:D33) -> 22
A35: → Kênh điểm cao nhất | B35: =IF(AND(B34>=C34,B34>=D34),"PLG",IF(C34>=D34,"Sales-Led","Partner-Led")) -> Partner-Led
A37: E. CHỐT KÊNH
A38: ★ Kênh tôi chọn cho 90 ngày đầu | B38: Partner-Led | D38: ĐÚNG 1 kênh. Chọn 2 kênh trở lên bị trừ điểm. | E38: Thắng sát điểm (22 vs 20 PLG). Lý do quyết định: containment phụ thuộc chất lượng catalog/tồn kho — dữ liệu đó nằm trong Haravan.
A39: Nếu Partner-Led: TÊN CÔNG TY partner | B39: Haravan (kho ứng dụng Haravan Apps — docs.haravan.com; HaraSocial) | D39: 'Các nền tảng trong ngành' = chưa có kênh
A40: Đã nói chuyện với họ chưa? (Rồi / Chưa) | B40: Chưa | E40: Sẽ gửi đề xuất trước 16/10/2026; cần câu trả lời có/không trước 30/10/2026.
A41: Bạn mang lại giá trị gì cho partner? | B41: (1) Lấp khoảng trống so với Sapo (đã có 'Chat hợp kênh AI') mà Haravan không phải tự build; (2) mỗi hội thoại AI xử lý xong tạo đơn nháp ngay trong Haravan → thêm đơn/GMV chạy qua Haravan; (3) chia sẻ doanh thu app (giả định 20%, cần xác nhận).
A42: Nếu rơi vào vùng không khả thi — lối thoát nào? | B42: Lối thoát = Partner-Led. 30 ngày tới: đăng ký tài khoản developer Haravan + build private app cho 5 shop pilot (đến 19/10), gửi đề xuất partner kèm số liệu tuần 1. Nếu đến 30/10 Haravan từ chối listing → chuyển KiotViet. | D42: Giảm giá để tự phục vụ / tăng giá + service / Partner-Led

Sheet 5_90Day_Plan
A1: TAB 5 — PAIN MOMENT · 90-DAY PLAN · EVIDENCE PACK
A2: Trạm 5 và Trạm 6.
A4: A. PAIN MOMENT — phải đủ 3 phần
A5: MẤY GIỜ khách đau nhất? | B5: 21h00–23h30 — giờ inbox dồn sau khi đăng bài/livestream lúc 20h (giả thuyết, đo bằng log giờ tin nhắn của pilot).
A6: Lúc đó họ ĐANG LÀM GÌ? | B6: Chủ shop vừa đóng gói đơn cho sáng mai vừa trả lời 40–60 tin 'giá bao nhiêu? còn size M không? ship HN mấy ngày?'; trả lời chậm thì khách nhắn shop khác.
A7: Họ đang DÙNG APP / KÊNH NÀO? | B7: Inbox Fanpage trên điện thoại qua app HaraSocial (hoặc Meta Business Suite); hàng và tồn kho nằm trong Haravan.
A8: → Điểm nhúng cụ thể của bạn | B8: Haravan app (OAuth vào cửa hàng Haravan: đọc sản phẩm/tồn kho, tạo đơn nháp) + Messenger Platform webhook trên chính Fanpage → AI trả lời NGAY TRONG inbox shop đang dùng, chủ shop thấy hết trên HaraSocial. Không có website/app mới. | D8: Một bề mặt tích hợp có tên, không phải 'website của chúng tôi'
A10: B. 90-DAY PLAN
B11: THÁNG 1 — Học | C11: THÁNG 2–3 — Đòn bẩy | D11: THÁNG 4+ — Mở rộng
A12: Kênh sử dụng | B12: Founder-led: tự tìm & onboard tận tay 5 shop thời trang dùng Haravan (nhóm cộng đồng Haravan, người quen). | C12: Partner-Led: private app → listing trên Haravan Apps + đề xuất co-marketing (webinar, email tới merchant HaraSocial). | D12: Vẫn Haravan; mở ngách liền kề giày dép/túi xách (cùng cấu trúc câu hỏi size/còn hàng/ship → tái dùng eval).
A13: Mục tiêu số khách | B13: 5 shop pilot (miễn phí 4 tuần), ≥3 shop đồng ý trả tiền từ tháng 2. | C13: 30 shop trả tiền tới ngày 90 (≈123tr₫ MRR). | D13: Chỉ mở rộng khi: containment thật ≥75%, GM thật ≥60%, ≥30 shop trả tiền, churn <8%/tháng.
A14: Việc cụ thể 1 | B14: Đọc 100% log tuần 1; gán nhãn 300 hội thoại thành bộ eval. | C14: Đưa Pilot Report + Eval Results cho team đối tác Haravan; xin listing. | D14: Eval riêng cho giày dép/túi xách (200 hội thoại) trước khi bán.
A15: Việc cụ thể 2 | B15: Phỏng vấn 5 chủ shop: lương trực page, số đơn mất ban đêm → kiểm chứng 2 con số neo giá. | C15: Tuyển 1 QA part-time; viết onboarding tự động (sync catalog ≤10 phút). | D15: Đàm phán rev-share chính thức; thử gói năm trả trước.
A16: Việc cụ thể 3 | B16: Đo containment, tỷ lệ báo giá đúng, token thực/hội thoại → cập nhật tab 1. | C16: A/B: tin nhắn chào trong app store vs. webinar để biết nguồn cài nào ra shop trả tiền. | D16: Đánh giá KiotViet làm partner thứ 2 (chỉ khi Haravan đã thắng).
A17: KPI đo được | B17: Containment đo trên ≥3.000 hội thoại; 100% câu báo giá/tồn kho khớp Haravan; 3/5 shop đồng ý trả tiền. | C17: 30 shop trả tiền · activation ≥60% (sync catalog + 50 hội thoại xử lý xong trong 7 ngày) · containment ≥70% · CAC ≤3tr₫/shop. | D17: GM thật ≥60% · NRR ≥100% · containment ngách mới ≥70%.
A18: Người chịu trách nhiệm | B18: Nguyễn Văn Biển (founder) | C18: Nguyễn Văn Biển · QA part-time (tuyển tháng 2) | D18: Nguyễn Văn Biển
A19: Tháng 1 là giai đoạn HỌC, không phải scale. Kế hoạch 'tháng 1 lấy 200 khách ở 5 ngành' là kế hoạch chưa ai từng thử làm.
A21: C. EVIDENCE PACK — 3 tài sản bán hàng
A22: Tài sản | B22: Đã có? (Rồi/Chưa) | C22: Nội dung 1 câu — hoặc việc cần làm | D22: Người phụ trách · Deadline
A23: 1. Eval Results | B23: Chưa | C23: Bộ eval 300 hội thoại thật (ẩn danh) từ 5 shop pilot: đo % xử lý đúng, % báo giá/tồn kho khớp Haravan, % chuyển người đúng chỗ. Mục tiêu: 'xử lý đúng ≥70%; 30% còn lại chuyển chủ shop'. | D23: Nguyễn Văn Biển · 13/11/2026
A24: 2. Procurement Q&A (Risk Checklist) | B24: Bản nháp | C24: (1) Hallucinate: AI KHÔNG tự sinh giá/tồn kho — chỉ đọc từ Haravan qua tool; không chắc, khiếu nại, đổi trả, giá sỉ → chuyển người. (2) Train model: dùng Claude API (điều khoản thương mại của Anthropic: không train trên dữ liệu khách — phải trích dẫn điều khoản cụ thể); không dùng hội thoại shop A cho shop B. (3) CaTối dừng: sản phẩm/đơn vẫn ở Haravan, hội thoại vẫn ở Fanpage; log của CaTối export CSV bất kỳ lúc nào, xoá trong 30 ngày khi ngừng. Rà soát theo Luật BVDLCN. | D24: Nguyễn Văn Biển · bản chính thức + rà soát pháp lý 30/10/2026
A25: 3. Pilot Report | B25: Chưa | C25: Pilot 4 tuần với 5 shop (19/10–15/11/2026): '__ tuần, __ hội thoại, containment __%, tiết kiệm __ giờ trực/tuần cho chủ shop'. | D25: Nguyễn Văn Biển · 20/11/2026
A26: Ô nào CHƯA CÓ thì ghi deadline — đừng bỏ trống. Thành thật về khoảng trống được điểm cao hơn bịa nội dung.
A28: D. BÀI TEST NGƯỜI LẠ — nhóm khác đọc One-Pager trong 2 phút
A29: Họ trả lời được: bán gì, cho ai, tính tiền theo đơn vị nào? (Được/Không) | B29: Được | E29: Nhóm đọc nhận ra ngay: AI trực inbox Facebook cho shop thời trang dùng Haravan, tính tiền theo hội thoại xử lý xong. Không cần hỏi lại mục này.
A30: Họ trả lời được: có lãi trên mỗi đơn vị không, số nào chứng minh? (Được/Không) | B30: Được | E30: Nhóm đọc thấy được: Cost/Job $0,047, GM 68,4%. Hỏi lại 1 lần: 'breakeven 55% nghĩa là sao?' → giải thích containment.
A31: Họ trả lời được: tiếp cận khách qua đâu, vì sao kênh đó? (Được/Không) | B31: Được | E31: Nhóm đọc nhận ra: Partner-Led qua Haravan Apps. Hiểu lý do vì dữ liệu catalog nằm trong Haravan.
A32: Số câu họ phải hỏi lại (mục tiêu ≤ 3) | B32: 1 | E32: Tổng 1 câu hỏi lại (breakeven containment). Đạt mục tiêu ≤ 3.

Sheet 6_Benchmarks
A1: TAB 6 — BENCHMARKS (CHỈ ĐỌC)
A2: Giá chốt ngày 26/08/2026. Dòng có ⏳ là GIÁ KHUYẾN MẠI CÓ HẠN — phải kiểm tra lại.
A3: NGÀY BẠN KIỂM TRA LẠI GIÁ | B3: 08/10/2026 | D3: Bắt buộc điền — Rubric có chấm mục này
A5: Nhóm | B5: Mục | C5: Giá | D5: Đơn vị | E5: Nguồn | F5: Kiểm tra 08/10/2026
A6: LLM | B6: Claude Opus 5 — input / output | C6: 5,00 / 25,00 | D6: $ / 1M token | E6: platform.claude.com/docs/en/about-claude/pricing | F6: Không đổi ($5/$25). Không dùng trong model.
A7: LLM | B7: Claude Sonnet 5 — input / output | C7: 2,00 / 10,00 | D7: $ / 1M token | E7: platform.claude.com/docs/en/about-claude/pricing | F7: ĐÃ ĐỔI TRẠNG THÁI: $2/$10 nay là giá CHUẨN; đợt tăng lên $3/$15 từ 01/09/2026 đã huỷ.
A8: LLM | B8: Claude Haiku 4.5 — input / output | C8: 1,00 / 5,00 | D8: $ / 1M token | E8: platform.claude.com/docs/en/about-claude/pricing | F8: Không đổi ($1/$5; cache write 5' $1,25 · 1h $2 · read $0,10). ← GIÁ DÙNG TRONG MODEL.
A9: LLM | B9: Claude — cache write 5' / cache read | C9: 1,25× / 0,10× input | D9: hệ số | E9: platform.claude.com/docs/en/about-claude/pricing | F9: Không đổi với Haiku 4.5. Lưu ý: Opus 5.5/Sonnet 5.5 cache read chỉ 0,05× input.
A10: LLM | B10: ⏳ OpenAI GPT-5.6 Sol — input / output | C10: 4,00 / 20,00 | D10: $ / 1M token | E10: developers.openai.com/api/docs/pricing (KM 21/08–21/11/2026; list 5,00/30,00) | F10: Không kiểm tra lại — không dùng trong model (KM hết hạn 21/11/2026).
A11: LLM | B11: OpenAI GPT-5.6 Luna — input / output | C11: 0,20 / 1,20 | D11: $ / 1M token | E11: developers.openai.com/api/docs/pricing | F11: Không kiểm tra lại — không dùng trong model.
A12: LLM | B12: OpenAI — cached input / Batch API | C12: 10% input / −50% | D12: hệ số | E12: developers.openai.com/api/docs/pricing | F12: Không kiểm tra lại — không dùng trong model.
A13: LLM | B13: Gemini 3.1 Pro — input / output (≤200k) | C13: 2,00 / 12,00 | D13: $ / 1M token | E13: ai.google.dev/gemini-api/docs/pricing | F13: Không kiểm tra lại — không dùng trong model.
A14: LLM | B14: ⏳ Gemini 3.7 Flash — input / output | C14: 0,75 / 3,75 | D14: $ / 1M token | E14: ai.google.dev/gemini-api/docs/pricing (KM đến 31/12/2026; sau đó 1,50/7,50) | F14: Vẫn KM: $0,75/$3,75 đến 31/12/2026 → $1,50/$7,50 từ 01/01/2027 (cached $0,075 → $0,15). Không chọn làm base vì giá gấp đôi sau 12 tuần.
A15: STT | B15: Deepgram Nova-3 — pre-recorded | C15: 0,0043 | D15: $ / phút | E15: deepgram.com/pricing
A16: STT | B16: ⏳ Deepgram Nova-3 — streaming | C16: list 0,0077 · KM 0,0048 | D16: $ / phút | E16: deepgram.com/pricing — đang khuyến mại, kiểm tra lại
A17: STT | B17: AssemblyAI Universal-2 — async | C17: 0,0025 | D17: $ / phút | E17: assemblyai.com/pricing
A18: STT | B18: OpenAI gpt-4o-mini-transcribe | C18: 0,0030 | D18: $ / phút | E18: developers.openai.com/api/docs/pricing
A19: TTS | B19: Google Cloud TTS — Standard | C19: 4,00 | D19: $ / 1M ký tự | E19: cloud.google.com/text-to-speech/pricing (rẻ nhất)
A20: TTS | B20: OpenAI tts-1 | C20: 15,00 | D20: $ / 1M ký tự | E20: developers.openai.com/api/docs/pricing
A21: TTS | B21: ElevenLabs Flash / Turbo | C21: 50,00 | D21: $ / 1M ký tự | E21: elevenlabs.io/pricing/api
A22: TTS | B22: ElevenLabs v3 / v2 Multilingual | C22: 100,00 | D22: $ / 1M ký tự | E22: elevenlabs.io/pricing/api
A23: Quy đổi | B23: Tốc độ nói | C23: ≈ 900 | D23: ký tự / phút | E23: ≈150 từ/phút — dùng để đổi phút ↔ ký tự
A24: Lưu ý | B24: Google TTS — ký tự CJK | C24: tính là 1 ký tự | D24: — | E24: cloud.google.com/text-to-speech/pricing (KHÔNG phải ×2)
A25: Lưu ý | B25: Google STT — tính theo kênh | C25: 4 kênh × 120s = 480s | D25: — | E25: cloud.google.com/speech-to-text/pricing
A26: Lưu ý | B26: Streaming vs async STT | C26: 1× đến ~5× | D26: hệ số | E26: Tuỳ nhà cung cấp — AssemblyAI 1,0× · Google ~5×. Đừng dùng hệ số chung
A27: Sản phẩm | B27: Intercom Fin — resolution | C27: 0,99 | D27: $ / outcome | E27: fin.ai/pricing | F27: Không đổi: $0,99/outcome; tối thiểu 50 outcome/tháng trên helpdesk bên thứ ba.
A28: Sản phẩm | B28: Intercom Fin — qualification (sales) | C28: 9,99 | D28: $ / outcome | E28: fin.ai/pricing
A29: Sản phẩm | B29: Zendesk — automated resolution | C29: 1,50 | D29: $ / resolution | E29: zendesk.com/blog/ai/agentic-ai/outcome-based-pricing/ (blog, không trên trang giá)
A30: Sản phẩm | B30: Salesforce Agentforce — Flex Credit | C30: 0,005 (action = 0,10) | D30: $ / credit | E30: salesforce.com/agentforce/pricing
A31: Sản phẩm | B31: Salesforce Agentforce — conversation | C31: 2,00 | D31: $ / conversation | E31: salesforce.com/agentforce/pricing | F31: Không đổi: $2/conversation; Flex Credits $500/100k; $5/user/tháng.
A32: Sản phẩm | B32: GitHub Copilot — AI Credit | C32: 0,01 | D32: $ / credit | E32: docs.github.com/en/copilot/get-started/plans
A33: Sản phẩm | B33: GitHub Copilot Business / Enterprise | C33: 19 / 39 | D33: $ / seat / tháng | E33: docs.github.com/en/copilot/get-started/plans
A34: Sản phẩm | B34: Notion — Business / credits | C34: 20 / 10 per 1.000 | D34: $ / member / tháng | E34: notion.com/pricing
A35: Benchmark | B35: Gross Margin AI-native 2026E | C35: ≈ 53% | D35: % | E35: ICONIQ, 2026 State of AI: The Builder's Economy (07/2026)
A36: Benchmark | B36: Gross Margin cloud (middle 50%) | C36: 60 – 80% | D36: % | E36: Bessemer, Scaling to $100 Million (2024)
A37: Benchmark | B37: Vertical AI — GM / model cost | C37: ≈65% / ≈10% doanh thu | D37: % | E37: Bessemer, State of the Cloud 2024
A38: Benchmark | B38: CAC payback SMB / Mid / Enterprise | C38: 12 / 18 / 24 | D38: tháng | E38: Bessemer, Scaling to $100 Million (2024)
A39: Benchmark | B39: LTV : CAC | C39: ≥ 3× | D39: lần | E39: David Skok, SaaS Metrics 2.0 (cập nhật 06/2026)
A40: Benchmark | B40: Cost per opportunity 2026 (theo phân khúc) | C40: 6.300 · 8.000 · 11.200 | D40: $ | E40: ICONIQ, State of GTM 2026 (tr.22)
A41: Benchmark | B41: ACV sàn cho inside sales | C41: ≈ 3.000 | D41: $ / năm | E41: Tomasz Tunguz (2016) — có kèm giả định để tính lại
...

Sheet 7_Stress_Test
A1: TAB 7 — STRESS TEST (tab thêm, không thuộc template)
A2: Mọi kịch bản dùng lại token/lượt, retry, infra, QA, containment và giá bán từ tab 1–2. Chỉ đổi giá model / quy mô / rev-share. Ô vàng = giả định kịch bản.
A4: A. ĐỔI MODEL — Cost/Job & GM ở cùng giá 3.900₫
A5: Kịch bản | B5: Input $/1M | C5: Output $/1M | D5: Cache write | E5: Cache read | F5: LLM/job thử | G5: Cost/Job | H5: GM | I5: Đèn
A6: BASE · Haiku 4.5, cache write 1h (= tab 1) | B6: 1 | C6: 5 | D6: 2 | E6: 0.1 | F6: =('1_Cost_Job'!$B$20*D6+('1_Cost_Job'!$B$19-1)*'1_Cost_Job'!$B$20*E6+'1_Cost_Job'!$B$19*'1_Cost_Job'!$B$21*B6+'1_Cost_Job'!$B$19*'1_Cost_Job'!$B$22*C6)/1000000 -> 0.02315 | G6: =(F6*(1+'1_Cost_Job'!$B$46)+'1_Cost_Job'!$B$43+'2_Pricing'!$B$30+'2_Pricing'!$B$31*(1-'1_Cost_Job'!$B$10))/'1_Cost_Job'!$B$10 -> 0.047041118 | H6: =1-G6/'2_Pricing'!$B$19 -> 0.6841008 | I6: =IF(H6>0.85,"Nghi ngờ >85%",IF(H6>=0.6,"An toàn",IF(H6>=0.5,"Cảnh báo","Nguy hiểm"))) -> An toàn
A7: Haiku 4.5, cache write 5 phút (lạc quan) | B7: 1 | C7: 5 | D7: 1.25 | E7: 0.1 | F7: =('1_Cost_Job'!$B$20*D7+('1_Cost_Job'!$B$19-1)*'1_Cost_Job'!$B$20*E7+'1_Cost_Job'!$B$19*'1_Cost_Job'!$B$21*B7+'1_Cost_Job'!$B$19*'1_Cost_Job'!$B$22*C7)/1000000 -> 0.020525 | G7: =(F7*(1+'1_Cost_Job'!$B$46)+'1_Cost_Job'!$B$43+'2_Pricing'!$B$30+'2_Pricing'!$B$31*(1-'1_Cost_Job'!$B$10))/'1_Cost_Job'!$B$10 -> 0.043066118 | H7: =1-G7/'2_Pricing'!$B$19 -> 0.71079445 | I7: =IF(H7>0.85,"Nghi ngờ >85%",IF(H7>=0.6,"An toàn",IF(H7>=0.5,"Cảnh báo","Nguy hiểm"))) -> An toàn
A8: Nâng lên Sonnet 5.5 (nếu Haiku hiểu sai teencode) | B8: 2 | C8: 10 | D8: 4 | E8: 0.1 | F8: =('1_Cost_Job'!$B$20*D8+('1_Cost_Job'!$B$19-1)*'1_Cost_Job'!$B$20*E8+'1_Cost_Job'!$B$19*'1_Cost_Job'!$B$21*B8+'1_Cost_Job'!$B$19*'1_Cost_Job'!$B$22*C8)/1000000 -> 0.04455 | G8: =(F8*(1+'1_Cost_Job'!$B$46)+'1_Cost_Job'!$B$43+'2_Pricing'!$B$30+'2_Pricing'!$B$31*(1-'1_Cost_Job'!$B$10))/'1_Cost_Job'!$B$10 -> 0.079446832 | H8: =1-G8/'2_Pricing'!$B$19 -> 0.46648396 | I8: =IF(H8>0.85,"Nghi ngờ >85%",IF(H8>=0.6,"An toàn",IF(H8>=0.5,"Cảnh báo","Nguy hiểm"))) -> Nguy hiểm
A9: Hạ xuống Haiku 5.5 (sau khi eval đạt) | B9: 0.1 | C9: 0.5 | D9: 0.2 | E9: 0.01 | F9: =('1_Cost_Job'!$B$20*D9+('1_Cost_Job'!$B$19-1)*'1_Cost_Job'!$B$20*E9+'1_Cost_Job'!$B$19*'1_Cost_Job'!$B$21*B9+'1_Cost_Job'!$B$19*'1_Cost_Job'!$B$22*C9)/1000000 -> 0.002315 | G9: =(F9*(1+'1_Cost_Job'!$B$46)+'1_Cost_Job'!$B$43+'2_Pricing'!$B$30+'2_Pricing'!$B$31*(1-'1_Cost_Job'!$B$10))/'1_Cost_Job'!$B$10 -> 0.015490975 | H9: =1-G9/'2_Pricing'!$B$19 -> 0.89597214 | I9: =IF(H9>0.85,"Nghi ngờ >85%",IF(H9>=0.6,"An toàn",IF(H9>=0.5,"Cảnh báo","Nguy hiểm"))) -> Nghi ngờ >85%
A10: ⏳ Gemini 3.7 Flash — giá KM đến 31/12/2026 | B10: 0.75 | C10: 3.75 | D10: 0.75 | E10: 0.075 | F10: =('1_Cost_Job'!$B$20*D10+('1_Cost_Job'!$B$19-1)*'1_Cost_Job'!$B$20*E10+'1_Cost_Job'!$B$19*'1_Cost_Job'!$B$21*B10+'1_Cost_Job'!$B$19*'1_Cost_Job'!$B$22*C10)/1000000 -> 0.0147375 | G10: =(F10*(1+'1_Cost_Job'!$B$46)+'1_Cost_Job'!$B$43+'2_Pricing'!$B$30+'2_Pricing'!$B$31*(1-'1_Cost_Job'!$B$10))/'1_Cost_Job'!$B$10 -> 0.03430219 | H10: =1-G10/'2_Pricing'!$B$19 -> 0.7696476 | I10: =IF(H10>0.85,"Nghi ngờ >85%",IF(H10>=0.6,"An toàn",IF(H10>=0.5,"Cảnh báo","Nguy hiểm"))) -> An toàn
A11: Gemini 3.7 Flash — giá list từ 01/01/2027 | B11: 1.5 | C11: 7.5 | D11: 1.5 | E11: 0.15 | F11: =('1_Cost_Job'!$B$20*D11+('1_Cost_Job'!$B$19-1)*'1_Cost_Job'!$B$20*E11+'1_Cost_Job'!$B$19*'1_Cost_Job'!$B$21*B11+'1_Cost_Job'!$B$19*'1_Cost_Job'!$B$22*C11)/1000000 -> 0.029475 | G11: =(F11*(1+'1_Cost_Job'!$B$46)+'1_Cost_Job'!$B$43+'2_Pricing'!$B$30+'2_Pricing'!$B$31*(1-'1_Cost_Job'!$B$10))/'1_Cost_Job'!$B$10 -> 0.056618975 | H11: =1-G11/'2_Pricing'!$B$19 -> 0.6197818 | I11: =IF(H11>0.85,"Nghi ngờ >85%",IF(H11>=0.6,"An toàn",IF(H11>=0.5,"Cảnh báo","Nguy hiểm"))) -> An toàn
A12: Đọc: Haiku 5.5 cho GM >85% → nếu thấy con số đó ở thực tế, kiểm tra lại có quên chi phí không. Sonnet 5.5 kéo GM xuống vùng nguy hiểm → model tier là biến sinh tử thứ 2 sau containment.
A14: B. QUY MÔ — infra cố định chia cho ít hội thoại
A15: Kịch bản | B15: Infra $/tháng | C15: Hội thoại thử/tháng | D15: Infra/job | E15: Cost/Job | F15: GM
A16: Pilot 5 shop | B16: 150 | C16: 7500 | D16: =B16/C16 -> 0.02 | E16: =('1_Cost_Job'!$B$31*(1+'1_Cost_Job'!$B$46)+D16+'2_Pricing'!$B$30)/'1_Cost_Job'!$B$10 -> 0.06846969 | F16: =1-E16/'2_Pricing'!$B$19 -> 0.5401997
A17: 30 shop (giả định tab 1) | B17: 190 | C17: 45000 | D17: =B17/C17 -> 0.0042222222 | E17: =('1_Cost_Job'!$B$31*(1+'1_Cost_Job'!$B$46)+D17+'2_Pricing'!$B$30)/'1_Cost_Job'!$B$10 -> 0.045930007 | F17: =1-E17/'2_Pricing'!$B$19 -> 0.69156234
A18: 100 shop | B18: 400 | C18: 150000 | D18: =B18/C18 -> 0.0026666667 | E18: =('1_Cost_Job'!$B$31*(1+'1_Cost_Job'!$B$46)+D18+'2_Pricing'!$B$30)/'1_Cost_Job'!$B$10 -> 0.043707785 | F18: =1-E18/'2_Pricing'!$B$19 -> 0.70648541
A20: C. CHIA SẺ DOANH THU VỚI PARTNER (Haravan) — giảm doanh thu ròng/job
A21: Rev-share | B21: Doanh thu ròng/job | C21: GM trên doanh thu ròng | D21: Đèn
A22: 0 | B22: ='2_Pricing'!$B$19*(1-A22) -> 0.1489118 | C22: =1-'2_Pricing'!$B$5/B22 -> 0.6841008 | D22: =IF(C22>=0.6,"An toàn",IF(C22>=0.5,"Cảnh báo","Nguy hiểm")) -> An toàn
A23: 0.2 | B23: ='2_Pricing'!$B$19*(1-A23) -> 0.11912944 | C23: =1-'2_Pricing'!$B$5/B23 -> 0.605126 | D23: =IF(C23>=0.6,"An toàn",IF(C23>=0.5,"Cảnh báo","Nguy hiểm")) -> An toàn
A24: 0.3 | B24: ='2_Pricing'!$B$19*(1-A24) -> 0.10423826 | C24: =1-'2_Pricing'!$B$5/B24 -> 0.54871543 | D24: =IF(C24>=0.6,"An toàn",IF(C24>=0.5,"Cảnh báo","Nguy hiểm")) -> Cảnh báo
A25: Tỷ lệ rev-share Haravan chưa công bố — phải xác nhận trong cuộc nói chuyện đầu tiên. Trên 30% → phải tăng giá hoặc hạ model.
A27: D. NẾU ĐỔI SANG BIẾN THỂ B (CaTối tự trả lời ca khó cho shop)
A28: e — chi phí 1 ca escalate do CaTối xử lý | B28: ='1_Cost_Job'!$B$53/60*'1_Cost_Job'!$B$50 -> 0.13559131
A29: Cost/Job Biến thể B | B29: =('2_Pricing'!$B$29+'2_Pricing'!$B$30+B28*(1-'1_Cost_Job'!$B$10))/'1_Cost_Job'!$B$10 -> 0.10515168
A30: GM Biến thể B ở giá 3.900₫ | B30: =1-B29/'2_Pricing'!$B$19 -> 0.29386603
A31: Breakeven containment Biến thể B (GM 60%) | B31: =('2_Pricing'!$B$29+'2_Pricing'!$B$30+B28)/('2_Pricing'!$B$19*(1-'2_Pricing'!$B$32)+B28) -> 0.86351466
A32: Biến thể B GÃY margin: 30% ca chuyển người × 3 phút làm Cost/Job tăng ~2,2× → GM ~29%, cần containment ~86% mới đạt GM 60%. Giữ A cho tới khi eval chứng minh containment ≥86%.
A34: E. NỘI ĐỊA HOÁ CAC TELESALES VN (đối chiếu với ICONIQ ở tab 4)
A35: Chi phí 1 telesales fully-loaded / tháng (₫) | B35: 20000000 | C35: Giả định: lương+hoa hồng+BHXH.
A36: Deal chốt / telesales / tháng | B36: 5 | C36: Khớp quota $120k ở tab 4!B13.
A37: Chi phí lead / deal (₫) — ~10 lead × 150.000₫ | B37: 1500000 | C37: Giả định quảng cáo FB B2B.
A38: Hệ số quản lý + onboarding | B38: 1.5 | C38: Giả định.
A39: → CAC telesales VN ước tính / khách ($) | B39: =(B35/B36+B37)*B38/'1_Cost_Job'!$B$68 -> 315.00573
A40: → So với ngân sách CAC (tab 4!B9) | B40: =B39/'4_Channel_Fit'!B9 -> 0.24541364
A41: Kết luận trung thực: với chi phí nhân sự VN, telesales KHÔNG bị loại về số học (ICONIQ là benchmark Mỹ). Partner-Led vẫn thắng vì (1) catalog/tồn kho nằm ở Haravan quyết định containment, (2) 1 founder không nuôi được đội telesales trong 90 ngày.
A43: F. MÔ HÌNH GÃY KHI NÀO? (GM = 50%)
A44: Containment làm GM rơi xuống 50% (giữ nguyên giá, model) | B44: =('2_Pricing'!$B$29+'2_Pricing'!$B$30)/('2_Pricing'!$B$19*0.5) -> 0.44225888
A45: LLM/job tối đa trước khi GM rơi xuống 50% (containment 70%) | B45: =(('2_Pricing'!$B$19*0.5)*'1_Cost_Job'!$B$10-'1_Cost_Job'!$B$43-'2_Pricing'!$B$30)/(1+'1_Cost_Job'!$B$46) -> 0.041254101
A46: → gấp bao nhiêu lần LLM/job hiện tại | B46: =B45/'1_Cost_Job'!$B$31 -> 1.7820346

Sheet 8_AI_Critique_Log
A1: TAB 8 — NHẬT KÝ PHẢN BIỆN BẰNG AI (§4.7)
A2: Phần A (dòng 5–17): Claude chạy 3 prompt §4.7 (4.7.1, 4.7.3, 4.7.5). Phần B (dòng 19–): Nguyễn Văn Biển tự chạy lại 4.7.1 và 4.7.5 và tự ghi accept/reject.
A4: Prompt | B4: AI chỉ ra | C4: Quyết định | D4: Đã làm gì / vì sao
A5: 4.7.1 Cost/Job | B5: Quên token ẢNH khách gửi (chụp mẫu hỏi 'còn không?'). | C5: ACCEPT | D5: Nâng token fresh từ 1.000 → 1.400/lượt (tab 1!B21).
A6: 4.7.1 Cost/Job | B6: Cache 5 phút sẽ hết hạn vì khách inbox trả lời chậm → số lượt đọc cache bị thổi phồng. | C6: ACCEPT | D6: Dùng giá cache write 1 giờ $2 (tab 1!B17). Kịch bản 5 phút để ở tab 7.
A7: 4.7.1 Cost/Job | B7: Quên chi phí chạy eval định kỳ + observability. | C7: ACCEPT | D7: Gộp vào infra $0,005/job, có bảng chia nhỏ ở ghi chú tab 1!E41.
A8: 4.7.1 Cost/Job | B8: Mẫu số: chia job thử hay job hoàn thành? | C8: ACCEPT (đã đúng) | D8: Chia 1.050 job hoàn thành, không 1.500. Nếu chia sai, Cost/Job thấp hơn ~30% (tab 1!B66 vs tổng/1.500).
A9: 4.7.1 Cost/Job | B9: HITL 30% ca chuyển người — ai chịu? | C9: REJECT đưa vào COGS | D9: Biến thể A: chủ shop vẫn tự trả lời các ca này như hôm nay và không bị tính tiền. Ghi nhận: nếu CaTối tự gánh (Biến thể B) thì GM ~29% (tab 7-D) → chính vì vậy giữ A.
A10: 4.7.1 Cost/Job | B10: Batch API giảm 50%. | C10: REJECT | D10: Chat realtime trên Messenger, khách đang chờ. Batch chỉ dùng cho chạy eval.
A11: 4.7.1 Cost/Job | B11: Biến số giết mô hình: model tier. | C11: ACCEPT | D11: Nếu phải lên Sonnet 5.5, GM tụt ~47% (tab 7-A). Hành động: eval Haiku 4.5 vs 5.5 trên teencode trước khi chốt.
A12: 4.7.1 Cost/Job | B12: Giá dùng có phải KM không? | C12: ACCEPT | D12: Haiku 4.5 là giá list. Không dùng Gemini Flash KM làm base (tăng gấp đôi từ 01/01/2027).
A13: 4.7.3 Channel | B13: Với quota VN, deal/AE/ngày ≈0,26 → Sales-Led khả thi về số học; ICONIQ là benchmark Mỹ. | C13: PARTIAL | D13: Ghi nhận trung thực ở tab 7-E (CAC telesales VN). Vẫn chọn Partner-Led vì dữ liệu catalog ở Haravan và đội 1 người.
A14: 4.7.3 Channel | B14: Partner có thể tự build AI chat (như Sapo đã làm) hoặc từ chối listing. | C14: ACCEPT | D14: Phép thử 2 tuần: có/không trước 30/10/2026; fallback KiotViet. Ghi ở tab 4!B42.
A15: 4.7.3 Channel | B15: Pain Moment có đủ cụ thể để gọi tên bề mặt tích hợp không? | C15: ACCEPT (đạt) | D15: Đã gọi tên HaraSocial + Messenger webhook + Haravan API, không có website riêng.
... A17: 4.7.5 One-Pager | B17: Kiểm tra toán: Cost/Job × (1/(1−GM)) phải bằng giá. | C17: ACCEPT (đạt) | D17: Đã đối chiếu: các số trên One-Pager lấy từ giá trị Excel tính lại, không gõ tay.
A19: PHẦN B — TỰ CHẠY LẠI (Nguyễn Văn Biển · 08/10/2026)
A20: 4.7.1 Cost/Job | B20: AI hỏi: Tại sao không dùng Batch API để giảm 50% chi phí LLM? | C20: REJECT | D20: Đây là chat realtime — khách đang chờ trả lời trực tiếp trên Messenger. Batch API chỉ hợp lệ khi chạy eval offline, không dùng được trong luồng sản phẩm. Giữ nguyên quyết định.
A21: 4.7.1 Cost/Job | B21: AI hỏi: Retry 6% có cao không? Cần đo thực từ log. | C21: PARTIAL | D21: ACCEPT rằng đây là ước tính — chưa có log thực. REJECT đề xuất dùng 2% vì Messenger webhook có tỷ lệ duplicate gửi; 6% là số bảo thủ phù hợp giai đoạn MVP. Sẽ đo từ log pilot tháng 11.
A22: 4.7.1 Cost/Job | B22: AI hỏi: Nếu chủ shop dùng template trả lời nhanh (quick replies), token đầu vào sẽ khác — đã tính chưa? | C22: ACCEPT | D22: Chưa tính. Quick replies tạo token output ngắn hơn (~50 token thay vì 200) nhưng token input vẫn phải đọc toàn bộ lịch sử. Tác động nhỏ (<5%) — ghi nhận là giả định chưa kiểm chứng, đo trong pilot.
A23: 4.7.5 One-Pager | B23: AI hỏi: One-Pager chưa giải thích 'xử lý xong' nghĩa là gì cho người đọc lần đầu. | C23: ACCEPT | D23: Đúng — người ngoài không biết định nghĩa 24h/không có tin người gõ. Đã thêm chú thích ngắn '(AI trả lời, khách không nhắn lại trong 24h)' vào phần giá trong One-Pager.
A24: 4.7.5 One-Pager | B24: AI hỏi: Phần kênh không nêu timeline rõ ràng — 'chưa nói chuyện' có thể gây lo ngại. | C24: REJECT | D24: REJECT che giấu. Giữ nguyên câu 'Chưa nói chuyện — gửi đề xuất trước 16/10, cần câu trả lời trước 30/10'. Trung thực về trạng thái là điểm mạnh (đề cũng yêu cầu thành thật). Thêm fallback KiotViet để cho thấy đã có plan B.
